~/workspace/server$ python populate_airport_codes.py
Traceback (most recent call last):
  File "/home/runner/workspace/.pythonlibs/lib/python3.11/site-packages/django/db/backends/utils.py", line 89, in _execute
    return self.cursor.execute(sql, params)
           ^^^^^^^^^^^^^^^^^^^^^^^^^^^^^^^^
psycopg2.errors.UndefinedTable: relation "api_airportcode" does not exist
LINE 1: ..."created_at", "api_airportcode"."updated_at" FROM "api_airpo...
                                                             ^


The above exception was the direct cause of the following exception:

Traceback (most recent call last):
  File "/home/runner/workspace/server/populate_airport_codes.py", line 6413, in <module>
    populate_airport_codes()
  File "/home/runner/workspace/server/populate_airport_codes.py", line 6383, in populate_airport_codes
    airport, created = AirportCode.objects.get_or_create(
                       ^^^^^^^^^^^^^^^^^^^^^^^^^^^^^^^^^^
  File "/home/runner/workspace/.pythonlibs/lib/python3.11/site-packages/django/db/models/manager.py", line 87, in manager_method
    return getattr(self.get_queryset(), name)(*args, **kwargs)
           ^^^^^^^^^^^^^^^^^^^^^^^^^^^^^^^^^^^^^^^^^^^^^^^^^^^
  File "/home/runner/workspace/.pythonlibs/lib/python3.11/site-packages/django/db/models/query.py", line 916, in get_or_create
    return self.get(**kwargs), False
           ^^^^^^^^^^^^^^^^^^
  File "/home/runner/workspace/.pythonlibs/lib/python3.11/site-packages/django/db/models/query.py", line 633, in get
    num = len(clone)
          ^^^^^^^^^^
  File "/home/runner/workspace/.pythonlibs/lib/python3.11/site-packages/django/db/models/query.py", line 380, in __len__
    self._fetch_all()
  File "/home/runner/workspace/.pythonlibs/lib/python3.11/site-packages/django/db/models/query.py", line 1881, in _fetch_all
    self._result_cache = list(self._iterable_class(self))
                         ^^^^^^^^^^^^^^^^^^^^^^^^^^^^^^^^
  File "/home/runner/workspace/.pythonlibs/lib/python3.11/site-packages/django/db/models/query.py", line 91, in __iter__
    results = compiler.execute_sql(
              ^^^^^^^^^^^^^^^^^^^^^
  File "/home/runner/workspace/.pythonlibs/lib/python3.11/site-packages/django/db/models/sql/compiler.py", line 1560, in execute_sql
    cursor.execute(sql, params)
  File "/home/runner/workspace/.pythonlibs/lib/python3.11/site-packages/django/db/backends/utils.py", line 102, in execute
    return super().execute(sql, params)
           ^^^^^^^^^^^^^^^^^^^^^^^^^^^^
  File "/home/runner/workspace/.pythonlibs/lib/python3.11/site-packages/django/db/backends/utils.py", line 67, in execute
    return self._execute_with_wrappers(
           ^^^^^^^^^^^^^^^^^^^^^^^^^^^^
  File "/home/runner/workspace/.pythonlibs/lib/python3.11/site-packages/django/db/backends/utils.py", line 80, in _execute_with_wrappers
    return executor(sql, params, many, context)
           ^^^^^^^^^^^^^^^^^^^^^^^^^^^^^^^^^^^^
  File "/home/runner/workspace/.pythonlibs/lib/python3.11/site-packages/django/db/backends/utils.py", line 84, in _execute
    with self.db.wrap_database_errors:
  File "/home/runner/workspace/.pythonlibs/lib/python3.11/site-packages/django/db/utils.py", line 91, in __exit__
    raise dj_exc_value.with_traceback(traceback) from exc_value
  File "/home/runner/workspace/.pythonlibs/lib/python3.11/site-packages/django/db/backends/utils.py", line 89, in _execute
    return self.cursor.execute(sql, params)
           ^^^^^^^^^^^^^^^^^^^^^^^^^^^^^^^^
django.db.utils.ProgrammingError: relation "api_airportcode" does not exist
LINE 1: ..."created_at", "api_airportcode"."updated_at" FROM "api_airpo...
                                                             ^
