Watching for file changes with StatReloader
Performing system checks...

System check identified no issues (0 silenced).
August 11, 2025 - 12:11:43
Django version 4.2, using settings 'soar_backend.settings'
Starting development server at http://0.0.0.0:8000/
Quit the server with CONTROL-C.

[11/Aug/2025 12:11:43] "GET / HTTP/1.1" 200 236
Internal Server Error: /api/leads/
Traceback (most recent call last):
  File "/home/runner/workspace/.pythonlibs/lib/python3.11/site-packages/django/db/backends/utils.py", line 89, in _execute
    return self.cursor.execute(sql, params)
           ^^^^^^^^^^^^^^^^^^^^^^^^^^^^^^^^
psycopg2.errors.UndefinedTable: relation "api_leadhistory" does not exist
LINE 1: ...y"."metadata", "api_leadhistory"."timestamp" FROM "api_leadh...
                                                             ^


The above exception was the direct cause of the following exception:

Traceback (most recent call last):
  File "/home/runner/workspace/.pythonlibs/lib/python3.11/site-packages/django/core/handlers/exception.py", line 55, in inner
    response = get_response(request)
               ^^^^^^^^^^^^^^^^^^^^^
  File "/home/runner/workspace/.pythonlibs/lib/python3.11/site-packages/django/core/handlers/base.py", line 197, in _get_response
    response = wrapped_callback(request, *callback_args, **callback_kwargs)
               ^^^^^^^^^^^^^^^^^^^^^^^^^^^^^^^^^^^^^^^^^^^^^^^^^^^^^^^^^^^^
  File "/home/runner/workspace/.pythonlibs/lib/python3.11/site-packages/django/views/decorators/csrf.py", line 56, in wrapper_view
    return view_func(*args, **kwargs)
           ^^^^^^^^^^^^^^^^^^^^^^^^^^
  File "/home/runner/workspace/.pythonlibs/lib/python3.11/site-packages/rest_framework/viewsets.py", line 125, in view
    return self.dispatch(request, *args, **kwargs)
           ^^^^^^^^^^^^^^^^^^^^^^^^^^^^^^^^^^^^^^^
  File "/home/runner/workspace/.pythonlibs/lib/python3.11/site-packages/rest_framework/views.py", line 509, in dispatch
    response = self.handle_exception(exc)
               ^^^^^^^^^^^^^^^^^^^^^^^^^^
  File "/home/runner/workspace/.pythonlibs/lib/python3.11/site-packages/rest_framework/views.py", line 469, in handle_exception
    self.raise_uncaught_exception(exc)
  File "/home/runner/workspace/.pythonlibs/lib/python3.11/site-packages/rest_framework/views.py", line 480, in raise_uncaught_exception
    raise exc
  File "/home/runner/workspace/.pythonlibs/lib/python3.11/site-packages/rest_framework/views.py", line 506, in dispatch
    response = handler(request, *args, **kwargs)
               ^^^^^^^^^^^^^^^^^^^^^^^^^^^^^^^^^
  File "/home/runner/workspace/.pythonlibs/lib/python3.11/site-packages/rest_framework/mixins.py", line 43, in list
    return self.get_paginated_response(serializer.data)
                                       ^^^^^^^^^^^^^^^
  File "/home/runner/workspace/.pythonlibs/lib/python3.11/site-packages/rest_framework/serializers.py", line 768, in data
    ret = super().data
          ^^^^^^^^^^^^
  File "/home/runner/workspace/.pythonlibs/lib/python3.11/site-packages/rest_framework/serializers.py", line 253, in data
    self._data = self.to_representation(self.instance)
                 ^^^^^^^^^^^^^^^^^^^^^^^^^^^^^^^^^^^^^
  File "/home/runner/workspace/.pythonlibs/lib/python3.11/site-packages/rest_framework/serializers.py", line 686, in to_representation
    return [
           ^
  File "/home/runner/workspace/.pythonlibs/lib/python3.11/site-packages/rest_framework/serializers.py", line 687, in <listcomp>
    self.child.to_representation(item) for item in iterable
    ^^^^^^^^^^^^^^^^^^^^^^^^^^^^^^^^^^
  File "/home/runner/workspace/.pythonlibs/lib/python3.11/site-packages/rest_framework/serializers.py", line 522, in to_representation
    ret[field.field_name] = field.to_representation(attribute)
                            ^^^^^^^^^^^^^^^^^^^^^^^^^^^^^^^^^^
  File "/home/runner/workspace/.pythonlibs/lib/python3.11/site-packages/rest_framework/serializers.py", line 686, in to_representation
    return [
           ^
  File "/home/runner/workspace/.pythonlibs/lib/python3.11/site-packages/django/db/models/query.py", line 398, in __iter__
    self._fetch_all()
  File "/home/runner/workspace/.pythonlibs/lib/python3.11/site-packages/django/db/models/query.py", line 1881, in _fetch_all
    self._result_cache = list(self._iterable_class(self))
                         ^^^^^^^^^^^^^^^^^^^^^^^^^^^^^^^^
  File "/home/runner/workspace/.pythonlibs/lib/python3.11/site-packages/django/db/models/query.py", line 91, in __iter__
    results = compiler.execute_sql(
              ^^^^^^^^^^^^^^^^^^^^^
  File "/home/runner/workspace/.pythonlibs/lib/python3.11/site-packages/django/db/models/sql/compiler.py", line 1560, in execute_sql
    cursor.execute(sql, params)
  File "/home/runner/workspace/.pythonlibs/lib/python3.11/site-packages/django/db/backends/utils.py", line 102, in execute
    return super().execute(sql, params)
           ^^^^^^^^^^^^^^^^^^^^^^^^^^^^
  File "/home/runner/workspace/.pythonlibs/lib/python3.11/site-packages/django/db/backends/utils.py", line 67, in execute
    return self._execute_with_wrappers(
           ^^^^^^^^^^^^^^^^^^^^^^^^^^^^
  File "/home/runner/workspace/.pythonlibs/lib/python3.11/site-packages/django/db/backends/utils.py", line 80, in _execute_with_wrappers
    return executor(sql, params, many, context)
           ^^^^^^^^^^^^^^^^^^^^^^^^^^^^^^^^^^^^
  File "/home/runner/workspace/.pythonlibs/lib/python3.11/site-packages/django/db/backends/utils.py", line 84, in _execute
    with self.db.wrap_database_errors:
  File "/home/runner/workspace/.pythonlibs/lib/python3.11/site-packages/django/db/utils.py", line 91, in __exit__
    raise dj_exc_value.with_traceback(traceback) from exc_value
  File "/home/runner/workspace/.pythonlibs/lib/python3.11/site-packages/django/db/backends/utils.py", line 89, in _execute
    return self.cursor.execute(sql, params)
           ^^^^^^^^^^^^^^^^^^^^^^^^^^^^^^^^
django.db.utils.ProgrammingError: relation "api_leadhistory" does not exist
LINE 1: ...y"."metadata", "api_leadhistory"."timestamp" FROM "api_leadh...
                                                             ^

[11/Aug/2025 12:15:55] "GET /api/leads/? HTTP/1.1" 500 234407
Internal Server Error: /api/leads/
Traceback (most recent call last):
  File "/home/runner/workspace/.pythonlibs/lib/python3.11/site-packages/django/db/backends/utils.py", line 89, in _execute
    return self.cursor.execute(sql, params)
           ^^^^^^^^^^^^^^^^^^^^^^^^^^^^^^^^
psycopg2.errors.UndefinedTable: relation "api_leadhistory" does not exist
LINE 1: ...y"."metadata", "api_leadhistory"."timestamp" FROM "api_leadh...
                                                             ^


The above exception was the direct cause of the following exception:

Traceback (most recent call last):
  File "/home/runner/workspace/.pythonlibs/lib/python3.11/site-packages/django/core/handlers/exception.py", line 55, in inner
    response = get_response(request)
               ^^^^^^^^^^^^^^^^^^^^^
  File "/home/runner/workspace/.pythonlibs/lib/python3.11/site-packages/django/core/handlers/base.py", line 197, in _get_response
    response = wrapped_callback(request, *callback_args, **callback_kwargs)
               ^^^^^^^^^^^^^^^^^^^^^^^^^^^^^^^^^^^^^^^^^^^^^^^^^^^^^^^^^^^^
  File "/home/runner/workspace/.pythonlibs/lib/python3.11/site-packages/django/views/decorators/csrf.py", line 56, in wrapper_view
    return view_func(*args, **kwargs)
           ^^^^^^^^^^^^^^^^^^^^^^^^^^
  File "/home/runner/workspace/.pythonlibs/lib/python3.11/site-packages/rest_framework/viewsets.py", line 125, in view
    return self.dispatch(request, *args, **kwargs)
           ^^^^^^^^^^^^^^^^^^^^^^^^^^^^^^^^^^^^^^^
  File "/home/runner/workspace/.pythonlibs/lib/python3.11/site-packages/rest_framework/views.py", line 509, in dispatch
    response = self.handle_exception(exc)
               ^^^^^^^^^^^^^^^^^^^^^^^^^^
  File "/home/runner/workspace/.pythonlibs/lib/python3.11/site-packages/rest_framework/views.py", line 469, in handle_exception
    self.raise_uncaught_exception(exc)
  File "/home/runner/workspace/.pythonlibs/lib/python3.11/site-packages/rest_framework/views.py", line 480, in raise_uncaught_exception
    raise exc
  File "/home/runner/workspace/.pythonlibs/lib/python3.11/site-packages/rest_framework/views.py", line 506, in dispatch
    response = handler(request, *args, **kwargs)
               ^^^^^^^^^^^^^^^^^^^^^^^^^^^^^^^^^
  File "/home/runner/workspace/.pythonlibs/lib/python3.11/site-packages/rest_framework/mixins.py", line 43, in list
    return self.get_paginated_response(serializer.data)
                                       ^^^^^^^^^^^^^^^
  File "/home/runner/workspace/.pythonlibs/lib/python3.11/site-packages/rest_framework/serializers.py", line 768, in data
    ret = super().data
          ^^^^^^^^^^^^
  File "/home/runner/workspace/.pythonlibs/lib/python3.11/site-packages/rest_framework/serializers.py", line 253, in data
    self._data = self.to_representation(self.instance)
                 ^^^^^^^^^^^^^^^^^^^^^^^^^^^^^^^^^^^^^
  File "/home/runner/workspace/.pythonlibs/lib/python3.11/site-packages/rest_framework/serializers.py", line 686, in to_representation
    return [
           ^
  File "/home/runner/workspace/.pythonlibs/lib/python3.11/site-packages/rest_framework/serializers.py", line 687, in <listcomp>
    self.child.to_representation(item) for item in iterable
    ^^^^^^^^^^^^^^^^^^^^^^^^^^^^^^^^^^
  File "/home/runner/workspace/.pythonlibs/lib/python3.11/site-packages/rest_framework/serializers.py", line 522, in to_representation
    ret[field.field_name] = field.to_representation(attribute)
                            ^^^^^^^^^^^^^^^^^^^^^^^^^^^^^^^^^^
  File "/home/runner/workspace/.pythonlibs/lib/python3.11/site-packages/rest_framework/serializers.py", line 686, in to_representation
    return [
           ^
  File "/home/runner/workspace/.pythonlibs/lib/python3.11/site-packages/django/db/models/query.py", line 398, in __iter__
    self._fetch_all()
  File "/home/runner/workspace/.pythonlibs/lib/python3.11/site-packages/django/db/models/query.py", line 1881, in _fetch_all
    self._result_cache = list(self._iterable_class(self))
                         ^^^^^^^^^^^^^^^^^^^^^^^^^^^^^^^^
  File "/home/runner/workspace/.pythonlibs/lib/python3.11/site-packages/django/db/models/query.py", line 91, in __iter__
    results = compiler.execute_sql(
              ^^^^^^^^^^^^^^^^^^^^^
  File "/home/runner/workspace/.pythonlibs/lib/python3.11/site-packages/django/db/models/sql/compiler.py", line 1560, in execute_sql
    cursor.execute(sql, params)
  File "/home/runner/workspace/.pythonlibs/lib/python3.11/site-packages/django/db/backends/utils.py", line 102, in execute
    return super().execute(sql, params)
           ^^^^^^^^^^^^^^^^^^^^^^^^^^^^
  File "/home/runner/workspace/.pythonlibs/lib/python3.11/site-packages/django/db/backends/utils.py", line 67, in execute
    return self._execute_with_wrappers(
           ^^^^^^^^^^^^^^^^^^^^^^^^^^^^
  File "/home/runner/workspace/.pythonlibs/lib/python3.11/site-packages/django/db/backends/utils.py", line 80, in _execute_with_wrappers
    return executor(sql, params, many, context)
           ^^^^^^^^^^^^^^^^^^^^^^^^^^^^^^^^^^^^
  File "/home/runner/workspace/.pythonlibs/lib/python3.11/site-packages/django/db/backends/utils.py", line 84, in _execute
    with self.db.wrap_database_errors:
  File "/home/runner/workspace/.pythonlibs/lib/python3.11/site-packages/django/db/utils.py", line 91, in __exit__
    raise dj_exc_value.with_traceback(traceback) from exc_value
  File "/home/runner/workspace/.pythonlibs/lib/python3.11/site-packages/django/db/backends/utils.py", line 89, in _execute
    return self.cursor.execute(sql, params)
           ^^^^^^^^^^^^^^^^^^^^^^^^^^^^^^^^
django.db.utils.ProgrammingError: relation "api_leadhistory" does not exist
LINE 1: ...y"."metadata", "api_leadhistory"."timestamp" FROM "api_leadh...
                                                             ^

[11/Aug/2025 12:15:55] "GET /api/leads/? HTTP/1.1" 500 234406
^[[1;2D